Workbook

Sheet Water
C1: % Basic Access
A2: Country Name | B2: ISO | C2: 2013 | D2: 2014 | E2: 2015 | F2: 2016 | G2: 2017 | H2: 2018 | I2: 2019 | J2: 2020 | K2: 2021 | L2: 2022
A3: Afghanistan | B3: AFG | C3: 56.858142 | D3: 59.598158 | E3: 62.36966 | F3: 65.172162 | G3: 68.008872 | H3: 70.879941 | I3: 73.784643 | J3: 76.722255 | K3: 79.693078 | L3: 82.175371
A4: Albania | B4: ALB | C4: 92.631596 | D4: 93.020058 | E4: 93.394324 | F4: 93.754878 | G4: 94.102096 | H4: 94.436393 | I4: 94.758225 | J4: 95.068039 | K4: 95.081513 | L4: 95.094564
A5: Algeria | B5: DZA | C5: 92.970881 | D5: 93.192347 | E5: 93.409558 | F5: 93.622776 | G5: 93.831975 | H5: 94.037415 | I5: 94.23914 | J5: 94.43733 | K5: 94.632102 | L5: 94.661398 | M5: =COUNT(L5) -> 1
A6: American Samoa | B6: ASM | C6: 98.230055 | D6: 98.483729 | E6: 98.737403 | F6: 98.991078 | G6: 99 | H6: 99 | I6: 99 | J6: 99 | K6: 99 | M6: =COUNT(L6) -> 0
A7: Andorra | B7: AND | C7: 99 | D7: 99 | E7: 99 | F7: 99 | G7: 99 | H7: 99 | I7: 99 | J7: 99 | K7: 99 | L7: 99
A8: Angola | B8: AGO | C8: 52.757346 | D8: 53.541508 | E8: 54.316931 | F8: 55.084273 | G8: 55.84291 | H8: 56.591749 | I8: 56.883037 | J8: 57.167738 | K8: 57.446726 | L8: 57.719561
A9: Anguilla | B9: AIA | C9: 97.482274 | D9: 97.482274 | E9: 97.482274 | F9: 97.482274 | G9: 97.482274
A10: Antigua and Barbuda | B10: ATG | C10: 98.365594 | D10: 98.365475 | E10: 98.365362 | F10: 98.365262 | G10: 98.365175 | H10: 98.365101 | I10: 98.365039 | J10: 98.364994 | K10: 98.364957 | L10: 98.364936
A11: Argentina | B11: ARG | C11: 98.864199 | D11: 98.923248 | E11: 98.982308 | F11: 99
A12: Armenia | B12: ARM | C12: 99 | D12: 99 | E12: 99 | F12: 99 | G12: 99 | H12: 99 | I12: 99 | J12: 99 | K12: 99 | L12: 99
A13: Aruba | B13: ABW | C13: 97.869023 | D13: 97.869023 | E13: 97.869023 | F13: 97.869023
A14: Australia | B14: AUS | C14: 99 | D14: 99 | E14: 99 | F14: 99 | G14: 99 | H14: 99 | I14: 99 | J14: 99 | K14: 99 | L14: 99
A15: Austria | B15: AUT | C15: 99 | D15: 99 | E15: 99 | F15: 99 | G15: 99 | H15: 99 | I15: 99 | J15: 99 | K15: 99 | L15: 99
A16: Azerbaijan | B16: AZE | C16: 89.952855 | D16: 91.283153 | E16: 92.569324 | F16: 93.35316 | G16: 94.131233 | H16: 94.902977 | I16: 95.667748 | J16: 96.362082 | K16: 97.007102 | L16: 97.642187
A17: Bahamas | B17: BHS | C17: 98.801432 | D17: 98.844196 | E17: 98.88696 | F17: 98.88696 | G17: 98.88696 | H17: 98.88696 | I17: 98.88696
A18: Bahrain | B18: BHR | C18: 99 | D18: 99 | E18: 99 | F18: 99 | G18: 99 | H18: 99 | I18: 99 | J18: 99 | K18: 99 | L18: 99
A19: Bangladesh | B19: BGD | C19: 97.014062 | D19: 97.159664 | E19: 97.301101 | F19: 97.438391 | G19: 97.571493 | H19: 97.700412 | I19: 97.825137 | J19: 97.945676 | K19: 98.03302 | L19: 98.097063
A20: Barbados | B20: BRB | C20: 98.454442 | D20: 98.464443 | E20: 98.474445 | F20: 98.484446 | G20: 98.494448 | H20: 98.504449 | I20: 98.51445 | J20: 98.51445 | K20: 98.51445 | L20: 98.51445
A21: Belarus | B21: BLR | C21: 98.311918 | D21: 98.320361 | E21: 98.330856 | F21: 98.343334 | G21: 98.357755 | H21: 98.373998 | I21: 98.391987 | J21: 98.651573 | K21: 99 | L21: 99
A22: Belgium | B22: BEL | C22: 99 | D22: 99 | E22: 99 | F22: 99 | G22: 99 | H22: 99 | I22: 99 | J22: 99 | K22: 99 | L22: 99
A23: Belize | B23: BLZ | C23: 95.890186 | D23: 96.5423 | E23: 97.175591 | F23: 97.584541 | G23: 97.992578 | H23: 98.399293 | I23: 98.40055 | J23: 98.401956 | K23: 98.403508 | L23: 98.405234
A24: Benin | B24: BEN | C24: 65.2796 | D24: 65.523475 | E24: 65.762759 | F24: 65.997362 | G24: 66.227199 | H24: 66.452198 | I24: 66.672267 | J24: 66.887329 | K24: 67.125909 | L24: 67.36027
A25: Bermuda | B25: BMU | C25: 99 | D25: 99 | E25: 99 | F25: 99 | G25: 99 | H25: 99 | I25: 99 | J25: 99 | K25: 99 | L25: 99
A26: Bhutan | B26: BTN | C26: 95.709153 | D26: 96.605778 | E26: 97.486223 | F26: 98.186239 | G26: 98.659842 | H26: 98.764997 | I26: 98.872312 | J26: 98.981718 | K26: 99 | L26: 99
A27: Bolivia (Plurinational State of) | B27: BOL | C27: 89.250073 | D27: 89.820335 | E27: 90.384168 | F27: 90.941849 | G27: 91.492949 | H27: 92.038844 | I27: 92.565954 | J27: 93.087422 | K27: 93.603179 | L27: 94.11337
A28: Bonaire, Sint Eustatius and Saba | B28: BES | C28: 99 | D28: 99 | E28: 99 | F28: 99 | G28: 99 | H28: 99 | I28: 99 | J28: 99 | K28: 99 | L28: 99
A29: Bosnia and Herzegovina | B29: BIH | C29: 96.352004 | D29: 96.168128 | E29: 96.159843 | F29: 96.151264 | G29: 96.142359 | H29: 96.133174 | I29: 96.123701 | J29: 96.113897 | K29: 96.103823 | L29: 96.093474
... A48: Colombia | B48: COL | C48: 95.577977 | D48: 95.821896 | E48: 96.061409 | F48: 96.296592 | G48: 96.527365 | H48: 96.739501 | I48: 96.892525 | J48: 97.041024 | K48: 97.393817 | L48: 97.53776
A49: Comoros | B49: COM | C49: 80.997568 | D49: 80.206032 | E49: 80.131999 | F49: 80.148851 | G49: 80.167517 | H49: 80.187987 | I49: 80.210501
A50: Congo | B50: COG | C50: 69.059537 | D50: 70.107042 | E50: 71.149584 | F50: 72.186657 | G50: 73.21776 | H50: 73.406816 | I50: 73.59587 | J50: 73.784511 | K50: 73.972327
A51: Cook Islands | B51: COK | C51: 99 | D51: 99 | E51: 99 | F51: 99 | G51: 99 | H51: 99 | I51: 99 | J51: 99 | K51: 99 | L51: 99
A52: Costa Rica | B52: CRI | C52: 98.806782 | D52: 99 | E52: 99 | F52: 99 | G52: 99 | H52: 99 | I52: 99 | J52: 99 | K52: 99 | L52: 99
A53: Côte d'Ivoire | B53: CIV | C53: 72.019 | D53: 72.107137 | E53: 72.195237 | F53: 72.282605 | G53: 72.369466 | H53: 72.455743 | I53: 72.541058 | J53: 72.625345 | K53: 72.738267 | L53: 72.850926
A54: Croatia | B54: HRV
A55: Cuba | B55: CUB | C55: 93.447031 | D55: 93.563572 | E55: 93.680025 | F55: 93.796187 | G55: 93.91318 | H55: 94.030722 | I55: 94.148482 | J55: 94.266279 | K55: 94.557599 | L55: 94.652704
A56: Curaçao | B56: CUW | C56: 99 | D56: 99 | E56: 99 | F56: 99 | G56: 99
A57: Cyprus | B57: CYP | C57: 99 | D57: 99 | E57: 99 | F57: 99 | G57: 99 | H57: 99 | I57: 99 | J57: 99 | K57: 99 | L57: 99
A58: Czechia | B58: CZE | C58: 99 | D58: 99 | E58: 99 | F58: 99 | G58: 99 | H58: 99 | I58: 99 | J58: 99 | K58: 99 | L58: 99
...

Sheet Food
C1: % Undernourished
A2: Country Name | B2: ISO | C2: 2013 | D2: 2014 | E2: 2015 | F2: 2016 | G2: 2017 | H2: 2018 | I2: 2019 | J2: 2020 | K2: 2021
A3: Afghanistan | B3: AFG | C3: 20.8 | D3: 20.7 | E3: 21.3 | F3: 21.8 | G3: 22.7 | H3: 24 | I3: 26.9 | J3: 28.8 | K3: 30.1
A4: Albania | B4: ALB | C4: 4.4 | D4: 4.4 | E4: 4.3 | F4: 4.2 | G4: 4.2 | H4: 4.1 | I4: 4.1 | J4: 4.1 | K4: 4.1
A5: Algeria | B5: DZA | C5: 2.9 | D5: 2.7 | E5: 2.6 | F5: 2.6 | G5: 2.6 | H5: 2.5 | I5: 2.5 | J5: 2.5 | K5: 2.5
A6: American Samoa | B6: ASM
A7: Andorra | B7: AND
A8: Angola | B8: AGO | C8: 12.7 | D8: 12.5 | E8: 13.5 | F8: 14.4 | G8: 14.7 | H8: 15.2 | I8: 17.5 | J8: 20.1 | K8: 21.6
A9: Anguilla | B9: AIA
A10: Antigua and Barbuda | B10: ATG
A11: Argentina | B11: ARG | C11: 3 | D11: 2.7 | E11: 2.7 | F11: 2.9 | G11: 3.3 | H11: 3.4 | I11: 3.4 | J11: 3.3 | K11: 3.2
A12: Armenia | B12: ARM | C12: 2.5 | D12: 2.5 | E12: 2.5 | F12: 2.5 | G12: 2.5 | H12: 2.5 | I12: 2.5 | J12: 2.5 | K12: 2.5
A13: Aruba | B13: ABW
A14: Australia | B14: AUS | C14: 2.5 | D14: 2.5 | E14: 2.5 | F14: 2.5 | G14: 2.5 | H14: 2.5 | I14: 2.5 | J14: 2.5 | K14: 2.5
A15: Austria | B15: AUT | C15: 2.5 | D15: 2.5 | E15: 2.5 | F15: 2.5 | G15: 2.5 | H15: 2.5 | I15: 2.5 | J15: 2.5 | K15: 2.5
A16: Azerbaijan | B16: AZE | C16: 2.5 | D16: 2.5 | E16: 2.5 | F16: 2.5 | G16: 2.5 | H16: 2.5 | I16: 2.5 | J16: 2.5 | K16: 2.5
A17: Bahamas | B17: BHS
A18: Bahrain | B18: BHR
A19: Bangladesh | B19: BGD | C19: 15.6 | D19: 14.8 | E19: 14.8 | F19: 14.3 | G19: 13.6 | H19: 12.7 | I19: 11.8 | J19: 11.7 | K19: 11.2
A20: Barbados | B20: BRB | C20: 2.5 | D20: 2.5 | E20: 2.5 | F20: 2.6 | G20: 2.6 | H20: 2.5 | I20: 2.5 | J20: 2.5 | K20: 2.5
A21: Belarus | B21: BLR | C21: 2.5 | D21: 2.5 | E21: 2.5 | F21: 2.5 | G21: 2.5 | H21: 2.5 | I21: 2.5 | J21: 2.5 | K21: 2.5
A22: Belgium | B22: BEL | C22: 2.5 | D22: 2.5 | E22: 2.5 | F22: 2.5 | G22: 2.5 | H22: 2.5 | I22: 2.5 | J22: 2.5 | K22: 2.5
A23: Belize | B23: BLZ | C23: 6.3 | D23: 6.6 | E23: 6.8 | F23: 6.4 | G23: 6 | H23: 5.3 | I23: 4.8 | J23: 4.7 | K23: 4.9
A24: Benin | B24: BEN | C24: 8.2 | D24: 8.2 | E24: 8.1 | F24: 8.7 | G24: 9.5 | H24: 10.4 | I24: 10.6 | J24: 10.2 | K24: 9.9
A25: Bermuda | B25: BMU
A26: Bhutan | B26: BTN
A27: Bolivia (Plurinational State of) | B27: BOL | C27: 17.9 | D27: 17.1 | E27: 16 | F27: 14.9 | G27: 14.2 | H27: 13.8 | I27: 13.7 | J27: 16.2 | K27: 19.4
A28: Bonaire, Sint Eustatius and Saba | B28: BES
A29: Bosnia and Herzegovina | B29: BIH | C29: 2.5 | D29: 2.5 | E29: 2.5 | F29: 2.5 | G29: 2.5 | H29: 2.5 | I29: 2.5 | J29: 2.5 | K29: 2.5
A30: Botswana | B30: BWA | C30: 23 | D30: 23.3 | E30: 24.1 | F30: 25 | G30: 26.3 | H30: 26.4 | I30: 26.4 | J30: 24.5 | K30: 22.9
A31: Brazil | B31: BRA | C31: 2.8 | D31: 2.6 | E31: 2.5 | F31: 2.5 | G31: 2.5 | H31: 2.5 | I31: 2.5 | J31: 3.7 | K31: 4.7
A32: British Virgin Islands | B32: VGB
A33: Brunei Darussalam | B33: BRN
A34: Bulgaria | B34: BGR | C34: 3.8 | D34: 3.8 | E34: 3.7 | F34: 3.8 | G34: 3.1 | H34: 2.8 | I34: 2.7 | J34: 2.5 | K34: 2.5
A35: Burkina Faso | B35: BFA | C35: 13.2 | D35: 13.1 | E35: 13.3 | F35: 13.6 | G35: 13.7 | H35: 14 | I35: 14.6 | J35: 15.5 | K35: 16.2
A36: Burundi | B36: BDI
A37: Cabo Verde | B37: CPV | C37: 19.4 | D37: 20.7 | E37: 21.4 | F37: 21.7 | G37: 20.9 | H37: 19.8 | I37: 18.5 | J37: 18.1 | K37: 18.2
A38: Cambodia | B38: KHM | C38: 8 | D38: 7.5 | E38: 6.9 | F38: 6.5 | G38: 5.8 | H38: 4.8 | I38: 4.3 | J38: 4.6 | K38: 4.8
A39: Cameroon | B39: CMR | C39: 3.8 | D39: 4.1 | E39: 4.4 | F39: 5 | G39: 5.6 | H39: 5.9 | I39: 5.8 | J39: 5.6 | K39: 6.4
A40: Canada | B40: CAN | C40: 2.5 | D40: 2.5 | E40: 2.5 | F40: 2.5 | G40: 2.5 | H40: 2.5 | I40: 2.5 | J40: 2.5 | K40: 2.5
...

Sheet Housing
C1: Inadequate Housing % of Population
A2: Country Name | B2: ISO | C2: 2013 | D2: 2014 | E2: 2015 | F2: 2016 | G2: 2017 | H2: 2018 | I2: 2019 | J2: 2020 | K2: 2021 | L2: 2022
A3: Afghanistan | B3: AFG | C3: 2.396188 | D3: 2.396188 | E3: 2.396188 | F3: 54.479075 | G3: 54.479075 | H3: 54.479075 | I3: 54.479075 | J3: 54.479075 | K3: 54.479075 | L3: 54.479075
A4: Albania | B4: ALB | C4: 1.3068737 | D4: 1.3068737 | E4: 1.3068737 | F4: 1.3068737 | G4: 1.3068737 | H4: 0.13925181 | I4: 0.13925181 | J4: 0.13925181 | K4: 0.13925181 | L4: 0.13925181
A5: Algeria | B5: DZA | C5: 0.81320228 | D5: 0.81320228 | E5: 0.81320228 | F5: 0.81320228 | G5: 0.81320228 | H5: 0.81320228 | I5: 0.44245003 | J5: 0.44245003 | K5: 0.44245003 | L5: 0.44245003
A6: American Samoa | B6: ASM
A7: Andorra | B7: AND
A8: Angola | B8: AGO | F8: 44.128182 | G8: 44.128182 | H8: 44.128182 | I8: 44.128182 | J8: 44.128182 | K8: 44.128182 | L8: 44.128182
A9: Anguilla | B9: AIA
A10: Antigua and Barbuda | B10: ATG
A11: Argentina | B11: ARG | C11: 1.6 | D11: 1.6 | E11: 1.6 | J11: 44.128182 | K11: 44.128182 | L11: 44.128182
A12: Armenia | B12: ARM | C12: 0 | D12: 0 | E12: 0 | F12: 0.023653369 | G12: 0.023653369 | H12: 0.023653369 | I12: 0.023653369 | J12: 0.023653369 | K12: 0.023653369 | L12: 0.023653369
A13: Aruba | B13: ABW
A14: Australia | B14: AUS
A15: Austria | B15: AUT
A16: Azerbaijan | B16: AZE | C16: 1.7890519 | D16: 1.7890519 | E16: 1.7890519 | F16: 1.7890519
A17: Bahamas | B17: BHS
A18: Bahrain | B18: BHR
A19: Bangladesh | B19: BGD | C19: 35.14307 | D19: 38.683525 | E19: 38.683525 | F19: 38.683525 | G19: 38.683525 | H19: 38.683525 | I19: 23.329691 | J19: 23.329691 | K19: 23.329691 | L19: 23.329691
A20: Barbados | B20: BRB | C20: 0.2709889 | D20: 0.2709889 | E20: 0.2709889 | F20: 0.2709889 | G20: 0.2709889 | H20: 0.2709889 | I20: 0.2709889 | J20: 0.2709889 | K20: 0.2709889 | L20: 0.2709889
A21: Belarus | B21: BLR | C21: 0 | D21: 0 | E21: 0
A22: Belgium | B22: BEL
A23: Belize | B23: BLZ | C23: 1.603814 | D23: 1.603814 | E23: 1.603814 | F23: 2.8491478 | G23: 2.8491478 | H23: 2.8491478 | I23: 2.8491478 | J23: 2.8491478 | K23: 2.8491478 | L23: 2.8491478
A24: Benin | B24: BEN | C24: 32.59259 | D24: 44.337577 | E24: 44.337577 | F24: 44.337577 | G24: 44.337577 | H24: 42.913766 | I24: 42.913766 | J24: 42.913766 | K24: 42.913766 | L24: 42.913766
A25: Bermuda | B25: BMU
A26: Bhutan | B26: BTN | C26: 30.862819 | D26: 30.862819 | E26: 30.862819 | F26: 30.862819 | G26: 30.862819 | H26: 30.862819 | I26: 30.862819 | J26: 30.862819
A27: Bolivia (Plurinational State of) | B27: BOL | C27: 16.830294 | D27: 16.830294 | E27: 16.830294 | F27: 7.5000166 | G27: 7.5000166 | H27: 7.5000166 | I27: 7.5000166 | J27: 7.5000166 | K27: 7.5000166 | L27: 7.5000166
A28: Bonaire, Sint Eustatius and Saba | B28: BES
A29: Bosnia and Herzegovina | B29: BIH | C29: 0.04973027 | D29: 0.04973027 | E29: 0.04973027 | F29: 0.04973027 | G29: 0.04973027 | H29: 0.04973027 | I29: 0.04973027 | J29: 0.04973027 | K29: 0.04973027 | L29: 0.04973027
A30: Botswana | B30: BWA | F30: 9.0563616 | G30: 9.0563616 | H30: 9.0563616 | I30: 9.0563616 | J30: 9.0563616 | K30: 9.0563616 | L30: 9.0563616
A31: Brazil | B31: BRA | C31: 0.3 | D31: 0.3 | E31: 0.56737738 | F31: 0.56737738 | G31: 0.56737738 | H31: 0.56737738 | I31: 0.56737738 | J31: 0.56737738 | K31: 0.56737738 | L31: 0.56737738
A32: British Virgin Islands | B32: VGB
A33: Brunei Darussalam | B33: BRN
A34: Bulgaria | B34: BGR
A35: Burkina Faso | B35: BFA | C35: 71.740478 | D35: 71.740478 | E35: 71.740478 | F35: 71.740478 | G35: 71.740478 | H35: 71.740478 | I35: 71.740478 | J35: 71.740478
A36: Burundi | B36: BDI | C36: 76.36504 | D36: 76.36504 | E36: 76.36504 | F36: 76.36504 | G36: 70.60278 | H36: 70.60278 | I36: 70.60278 | J36: 70.60278 | K36: 70.60278 | L36: 70.60278
A37: Cabo Verde | B37: CPV
A38: Cambodia | B38: KHM | C38: 3.9 | D38: 21.795412 | E38: 21.795412 | F38: 21.795412 | G38: 21.795412 | H38: 21.795412 | I38: 21.795412 | J38: 21.795412 | K38: 21.795412 | L38: 4.5952475
A39: Cameroon | B39: CMR | C39: 34.47456 | D39: 38.972089 | E39: 38.972089 | F39: 38.972089 | G39: 38.972089 | H39: 36.977012 | I39: 36.977012 | J39: 36.977012 | K39: 36.977012 | L39: 36.977012
A40: Canada | B40: CAN
...

Sheet Employment
C1: Distressed Labor Rate
A2: Country Name | B2: ISO | C2: 2013 | D2: 2014 | E2: 2015 | F2: 2016 | G2: 2017 | H2: 2018 | I2: 2019 | J2: 2020 | K2: 2021 | L2: 2022 | M2: 2023
A3: Afghanistan | B3: AFG | C3: 0.58749152 | D3: 0.581377 | E3: 0.57638692 | F3: 0.56867159 | G3: 0.54108457 | H3: 0.48899913 | I3: 0.46478096 | J3: 0.47819857 | K3: 0.47050941 | L3: 0.69823633 | M3: 0.91120363
A4: Albania | B4: ALB | C4: 0.20214795 | D4: 0.23578955 | E4: 0.18742223 | F4: 0.17847607 | G4: 0.15357495 | H4: 0.13433007 | I4: 0.11952947 | J4: 0.13295152 | K4: 0.12970557 | L4: 0.11797685 | M4: 0.1174437
A5: Algeria | B5: DZA | C5: 0.1092736 | D5: 0.11197956 | E5: 0.12105265 | F5: 0.1105352 | G5: 0.12840773 | H5: 0.1295184 | I5: 0.13079411 | J5: 0.14982877 | K5: 0.14519906 | L5: 0.13299662 | M5: 0.12678003
A6: American Samoa | B6: ASM
A7: Andorra | B7: AND
A8: Angola | B8: AGO | C8: 0.46024592 | D8: 0.46203458 | E8: 0.48068577 | F8: 0.50425395 | G8: 0.52672785 | H8: 0.56030682 | I8: 0.57838229 | J8: 0.59920999 | K8: 0.60001901 | L8: 0.5945692 | M8: 0.59890395
A9: Anguilla | B9: AIA
A10: Antigua and Barbuda | B10: ATG
A11: Argentina | B11: ARG | C11: 0.078253932 | D11: 0.080293342 | E11: 0.08299877 | F11: 0.088531221 | G11: 0.091131515 | H11: 0.10149087 | I11: 0.10881468 | J11: 0.1265972 | K11: 0.096251207 | L11: 0.078386979 | M11: 0.072126191
A12: Armenia | B12: ARM | C12: 0.18809108 | D12: 0.17973732 | E12: 0.16719708 | F12: 0.17002538 | G12: 0.16100669 | H12: 0.17298645 | I12: 0.16527955 | J12: 0.14493383 | K12: 0.13721615 | L12: 0.10842102 | M12: 0.10509888
A13: Aruba | B13: ABW
A14: Australia | B14: AUS
A15: Austria | B15: AUT
A16: Azerbaijan | B16: AZE | C16: 0.051596729 | D16: 0.050998273 | E16: 0.051496988 | F16: 0.05189635 | G16: 0.051896266 | H16: 0.050898271 | I16: 0.051896287 | J16: 0.074251498 | K16: 0.062275594 | L16: 0.058330604 | M16: 0.05819199
A17: Bahamas | B17: BHS | C17: 0.16313432 | D17: 0.13951551 | E17: 0.12122851 | F17: 0.1284514 | G17: 0.09946354 | H17: 0.10135042 | I17: 0.10130755 | J17: 0.12915391 | K17: 0.11789168 | L17: 0.0998419 | M17: 0.093126551
A18: Bahrain | B18: BHR | C18: 0.015244531 | D18: 0.01517351 | E18: 0.015182959 | F18: 0.015432268 | G18: 0.015582759 | H18: 0.015300953 | I18: 0.015292618 | J18: 0.020359829 | K18: 0.017434663 | L18: 0.015487127 | M18: 0.013826776
A19: Bangladesh | B19: BGD | C19: 0.52446786 | D19: 0.51056476 | E19: 0.49995435 | F19: 0.48885497 | G19: 0.47439203 | H19: 0.45995948 | I19: 0.44889374 | J19: 0.44479476 | K19: 0.4291976 | L19: 0.39493377 | M19: 0.36919423
A20: Barbados | B20: BRB | C20: 0.18733999 | D20: 0.18750959 | E20: 0.16407927 | F20: 0.15302718 | G20: 0.15392198 | H20: 0.14917831 | I20: 0.14896783 | J20: 0.17030094 | K20: 0.16044015 | L20: 0.14875959 | M20: 0.14145258
A21: Belarus | B21: BLR | C21: 0.06063282 | D21: 0.060244326 | E21: 0.060261952 | F21: 0.059601163 | G21: 0.05783466 | H21: 0.048838662 | I21: 0.042675854 | J21: 0.041695867 | K21: 0.040918046 | L21: 0.037054631 | M21: 0.037052505
A22: Belgium | B22: BEL
A23: Belize | B23: BLZ | C23: 0.37604171 | D23: 0.36958018 | E23: 0.3625216 | F23: 0.3635564 | G23: 0.37164841 | H23: 0.38033597 | I23: 0.374212 | J23: 0.44462403 | K23: 0.39405994 | L23: 0.36408583 | M23: 0.3282807
A24: Benin | B24: BEN | C24: 0.73829248 | D24: 0.72443068 | E24: 0.73874908 | F24: 0.71917307 | G24: 0.64092166 | H24: 0.53533255 | I24: 0.46976619 | J24: 0.46852146 | K24: 0.44800199 | L24: 0.43806314 | M24: 0.42626804
A25: Bermuda | B25: BMU
A26: Bhutan | B26: BTN | C26: 0.13150044 | D26: 0.13671473 | E26: 0.12941647 | F26: 0.13404696 | G26: 0.13408515 | H26: 0.056948035 | I26: 0.077919551 | J26: 0.10160038 | K26: 0.07321361 | L26: 0.092426359 | M26: 0.08899329
A27: Bolivia (Plurinational State of) | B27: BOL | C27: 0.10739177 | D27: 0.1040613 | E27: 0.10720305 | F27: 0.13029763 | G27: 0.12450325 | H27: 0.11224856 | I27: 0.094834774 | J27: 0.13985148 | K27: 0.10694326 | L27: 0.088009322 | M27: 0.081610249
A28: Bonaire, Sint Eustatius and Saba | B28: BES
A29: Bosnia and Herzegovina | B29: BIH | C29: 0.28126095 | D29: 0.28067178 | E29: 0.28194747 | F29: 0.25823564 | G29: 0.20914849 | H29: 0.18730011 | I29: 0.15991206 | J29: 0.16166648 | K29: 0.1517504 | L29: 0.12954023 | M29: 0.10700598
A30: Botswana | B30: BWA | C30: 0.41224045 | D30: 0.41027325 | E30: 0.4501245 | F30: 0.44306536 | G30: 0.4381069 | H30: 0.42948614 | I30: 0.42910398 | J30: 0.46116808 | K30: 0.44734013 | L30: 0.44409176 | M30: 0.43653807
A31: Brazil | B31: BRA | C31: 0.11004144 | D31: 0.1001649 | E31: 0.12279859 | F31: 0.16148244 | G31: 0.17593262 | H31: 0.17115788 | I31: 0.16702596 | J31: 0.18628098 | K31: 0.18156303 | L31: 0.14372381 | M31: 0.12952284
A32: British Virgin Islands | B32: VGB
A33: Brunei Darussalam | B33: BRN
A34: Bulgaria | B34: BGR
A35: Burkina Faso | B35: BFA | C35: 0.72782528 | D35: 0.72110577 | E35: 0.71622602 | F35: 0.68493373 | G35: 0.65433745 | H35: 0.62100648 | I35: 0.60308942 | J35: 0.60591274 | K35: 0.58820732 | L35: 0.59979992 | M35: 0.59352314
A36: Burundi | B36: BDI | C36: 0.86449228 | D36: 0.85724813 | E36: 0.87015641 | F36: 0.87466436 | G36: 0.87796881 | H36: 0.8817707 | I36: 0.88398171 | J36: 0.88872996 | K36: 0.88710651 | L36: 0.88978784 | M36: 0.89029561
A37: Cabo Verde | B37: CPV | C37: 0.25768819 | D37: 0.24978348 | E37: 0.24147127 | F37: 0.23179263 | G37: 0.22020815 | H37: 0.21109694 | I37: 0.19739667 | J37: 0.23897498 | K37: 0.22034629 | L37: 0.18895105 | M37: 0.18140341
A38: Cambodia | B38: KHM | C38: 0.7373489 | D38: 0.69986203 | E38: 0.65936545 | F38: 0.60506218 | G38: 0.59509468 | H38: 0.58678849 | I38: 0.57959665 | J38: 0.54509583 | K38: 0.537094 | L38: 0.53762731 | M38: 0.54177063
A39: Cameroon | B39: CMR | C39: 0.49296381 | D39: 0.44960041 | E39: 0.43897184 | F39: 0.43317782 | G39: 0.43030146 | H39: 0.42570973 | I39: 0.42301988 | J39: 0.4287275 | K39: 0.4267163 | L39: 0.42404982 | M39: 0.42048961
A40: Canada | B40: CAN
...

Sheet Education
C1: Adult Literacy Rate
A2: Country Name | B2: Country Code | C2: 2013 | D2: 2014 | E2: 2015 | F2: 2016 | G2: 2017 | H2: 2018 | I2: 2019 | J2: 2020 | K2: 2021 | L2: 2022
A3: Afghanistan | B3: AFG | C3: 31.448851 | D3: 31.448851 | E3: 31.448851 | F3: 31.448851 | G3: 31.448851 | H3: 31.448851 | I3: 31.448851 | J3: 31.448851 | K3: 37.266041 | L3: 37.266041
A4: Albania | B4: ALB | C4: 97.246971 | D4: 97.246971 | E4: 97.246971 | F4: 97.246971 | G4: 97.246971 | H4: 97.246971 | I4: 97.246971 | J4: 97.246971 | K4: 97.246971 | L4: 98.5
A5: Algeria | B5: DZA | C5: 75.136047 | D5: 75.136047 | E5: 75.136047 | F5: 75.136047 | G5: 75.136047 | H5: 81.407837 | I5: 81.407837 | J5: 81.407837 | K5: 81.407837 | L5: 81.407837
A6: American Samoa | B6: ASM
A7: Andorra | B7: AND
A8: Angola | B8: AGO | D8: 66.030113 | E8: 66.030113 | F8: 66.030113 | G8: 66.030113 | H8: 66.030113 | I8: 66.030113 | J8: 66.030113 | K8: 66.030113 | L8: 72.400002
A9: Anguilla | B9: AIA
A10: Antigua and Barbuda | B10: ATG
A11: Argentina | B11: ARG
A12: Armenia | B12: ARM | C12: 99.744408 | D12: 99.744408 | E12: 99.744408 | F12: 99.744408 | G12: 99.736069 | H12: 99.736069 | I12: 99.736069 | J12: 99.788612 | K12: 99.788612 | L12: 99.788612
A13: Aruba | B13: ABW | C13: 96.822639 | D13: 96.822639 | E13: 96.822639 | F13: 96.822639 | G13: 96.822639 | H13: 96.822639 | I13: 96.822639 | J13: 97.989998 | K13: 97.989998 | L13: 97.989998
A14: Australia | B14: AUS
A15: Austria | B15: AUT
A16: Azerbaijan | B16: AZE | C16: 99.78936 | D16: 99.788986 | E16: 99.788063 | F16: 99.790062 | G16: 99.791229 | H16: 99.791229 | I16: 99.795982 | J16: 99.795982 | K16: 99.795982 | L16: 99.795982
A17: Bahamas | B17: BHS
A18: Bahrain | B18: BHR | C18: 92.300003 | D18: 92.300003 | E18: 92.300003 | F18: 92.300003 | G18: 92.300003 | H18: 92.300003 | I18: 92.300003 | J18: 92.300003 | K18: 92.300003 | L18: 97.872482
A19: Bangladesh | B19: BGD | C19: 61.015541 | D19: 61.0933 | E19: 65.137329 | F19: 72.75872 | G19: 72.892967 | H19: 73.912201 | I19: 74.684464 | J19: 74.908897 | K19: 76.362877 | L19: 76.362877
A20: Barbados | B20: BRB
A21: Belarus | B21: BLR | C21: 99.617058 | D21: 99.617058 | E21: 99.617058 | F21: 99.617058 | G21: 99.617058 | H21: 99.617058 | I21: 99.874001 | J21: 99.874001 | K21: 99.874001 | L21: 99.874001
A22: Belgium | B22: BEL
A23: Belize | B23: BLZ
A24: Benin | B24: BEN | C24: 32.948818 | D24: 32.948818 | E24: 32.948818 | F24: 32.948818 | G24: 32.948818 | H24: 32.948818 | I24: 32.948818 | J24: 32.948818 | K24: 32.948818 | L24: 47.099998
A25: Bermuda | B25: BMU
A26: Bhutan | B26: BTN | C26: 55.317558 | D26: 55.317558 | E26: 55.317558 | F26: 55.317558 | G26: 66.56115 | H26: 66.56115 | I26: 66.56115 | J26: 66.56115 | K26: 66.56115 | L26: 72.099998
A27: Bolivia (Plurinational State of) | B27: BOL | C27: 94.460571 | D27: 94.460571 | E27: 92.455078 | F27: 92.455078 | G27: 92.455078 | H27: 92.455078 | I27: 92.455078 | J27: 93.852562 | K27: 93.852562 | L27: 93.852562
A28: Bonaire, Sint Eustatius and Saba | B28: BES
A29: Bosnia and Herzegovina | B29: BIH | C29: 96.991768 | D29: 96.991768 | E29: 96.991768 | F29: 96.991768 | G29: 96.991768 | H29: 96.991768 | I29: 96.991768 | J29: 96.991768 | K29: 96.991768 | L29: 98.300003
A30: Botswana | B30: BWA | C30: 86.823181 | D30: 86.823181 | E30: 86.823181 | F30: 86.823181 | G30: 86.823181 | H30: 86.823181 | I30: 86.823181 | J30: 86.823181 | K30: 86.823181 | L30: 86.823181
A31: Brazil | B31: BRA | C31: 91.484238 | D31: 91.729431 | E31: 92.047897 | F31: 92.808441 | G31: 93.075821 | H31: 93.227501 | I31: 93.227501 | J31: 93.227501 | K31: 93.227501 | L31: 94.690002
A32: British Virgin Islands | B32: VGB
A33: Brunei Darussalam | B33: BRN | C33: 96.085564 | D33: 96.085564 | E33: 96.085564 | F33: 96.085564 | G33: 96.085564 | H33: 97.214111 | I33: 97.214111 | J33: 97.214111 | K33: 97.589996 | L33: 97.589996
A34: Bulgaria | B34: BGR | C34: 98.352448 | D34: 98.352448 | E34: 98.352448 | F34: 98.352448 | G34: 98.352448 | H34: 98.352448 | I34: 98.352448 | J34: 98.352448 | K34: 98.419998 | L34: 98.419998
A35: Burkina Faso | B35: BFA | C35: 28.293659 | D35: 34.5994 | E35: 34.5994 | F35: 34.5994 | G35: 34.5994 | H35: 39.345852 | I35: 29.66328 | J35: 29.66328 | K35: 29.66328 | L35: 34.490002
A36: Burundi | B36: BDI | C36: 48.084061 | D36: 61.513489 | E36: 61.513489 | F36: 61.513489 | G36: 68.375328 | H36: 68.375328 | I36: 68.375328 | J36: 68.375328 | K36: 68.375328 | L36: 75.540001
A37: Cabo Verde | B37: CPV | C37: 85.327789 | D37: 85.327789 | E37: 86.790291 | F37: 86.790291 | G37: 86.790291 | H37: 86.790291 | I37: 86.790291 | J37: 86.790291 | K37: 86.790291 | L37: 91
A38: Cambodia | B38: KHM | C38: 76.137962 | D38: 78.055092 | E38: 80.526489 | F38: 80.526489 | G38: 80.526489 | H38: 80.526489 | I38: 80.526489 | J38: 80.526489 | K38: 80.526489 | L38: 83.779999
A39: Cameroon | B39: CMR | C39: 71.290512 | D39: 71.290512 | E39: 71.290512 | F39: 71.290512 | G39: 71.290512 | H39: 77.071037 | I39: 77.071037 | J39: 78.230003 | K39: 78.230003 | L39: 78.230003
A40: Canada | B40: CAN
...

Sheet Gender
C1: Gender Index
A2: Country Name | B2: Country ISO | C2: 2013 | D2: 2014 | E2: 2015 | F2: 2016 | G2: 2017 | H2: 2018 | I2: 2020 | J2: 2021 | K2: 2022
A3: Afghanistan | B3: AFG | J3: 0.95 | K3: 0.95
A4: Albania | B4: ALB | C4: 0.93 | D4: 0.94 | E4: 0.95 | F4: 0.95 | G4: 0.97 | H4: 0.96 | I4: 0.96 | J4: 0.96 | K4: 0.96
A5: Algeria | B5: DZA | C5: 0.97 | D5: 0.97 | E5: 0.97 | F5: 0.97 | G5: 0.97 | H5: 0.96 | I5: 0.96 | J5: 0.96 | K5: 0.96
A6: American Samoa | B6: ASM
A7: Andorra | B7: AND
A8: Angola | B8: AGO | C8: 0.98 | D8: 0.98 | E8: 0.98 | F8: 0.98 | G8: 0.98 | H8: 0.98 | I8: 0.98 | J8: 0.98 | K8: 0.98
A9: Anguilla | B9: AIA
A10: Antigua and Barbuda | B10: ATG
A11: Argentina | B11: ARG | C11: 0.98 | D11: 0.98 | E11: 0.98 | F11: 0.98 | G11: 0.98 | H11: 0.98 | I11: 0.98 | J11: 0.98 | K11: 0.98
A12: Armenia | B12: ARM | C12: 0.95 | D12: 0.93 | E12: 0.94 | F12: 0.94 | G12: 0.94 | H12: 0.94 | I12: 0.95 | J12: 0.95 | K12: 0.95
A13: Aruba | B13: ABW
A14: Australia | B14: AUS | C14: 0.97 | D14: 0.97 | E14: 0.97 | F14: 0.97 | G14: 0.97 | H14: 0.97 | I14: 0.97 | J14: 0.97 | K14: 0.97
A15: Austria | B15: AUT | C15: 0.98 | D15: 0.98 | E15: 0.98 | F15: 0.98 | G15: 0.98 | H15: 0.97 | I15: 0.97 | J15: 0.97 | K15: 0.97
A16: Azerbaijan | B16: AZE | C16: 0.93 | D16: 0.94 | E16: 0.95 | F16: 0.95 | G16: 0.94 | H16: 0.94 | I16: 0.94 | J16: 0.94 | K16: 0.94
A17: Bahamas | B17: BHS | C17: 0.98 | D17: 0.98 | E17: 0.98 | F17: 0.98 | G17: 0.98 | H17: 0.98 | I17: 0.98 | J17: 0.98
A18: Bahrain | B18: BHR | C18: 0.96 | D18: 0.96 | E18: 0.96 | F18: 0.96 | G18: 0.96 | H18: 0.96 | I18: 0.96 | J18: 0.96 | K18: 0.96
A19: Bangladesh | B19: BGD | C19: 0.96 | D19: 0.97 | E19: 0.97 | F19: 0.97 | G19: 0.97 | H19: 0.97 | I19: 0.97 | J19: 0.96 | K19: 0.96
A20: Barbados | B20: BRB | C20: 0.98 | D20: 0.98 | E20: 0.98 | F20: 0.98 | G20: 0.97 | H20: 0.98 | I20: 0.98 | J20: 0.97 | K20: 0.97
A21: Belarus | B21: BLR | D21: 0.98 | E21: 0.98 | F21: 0.98 | G21: 0.98 | H21: 0.98 | I21: 0.98 | J21: 0.98 | K21: 0.98
A22: Belgium | B22: BEL | C22: 0.98 | D22: 0.98 | E22: 0.97 | F22: 0.97 | G22: 0.98 | H22: 0.97 | I22: 0.97 | J22: 0.97 | K22: 0.97
A23: Belize | B23: BLZ | C23: 0.98 | D23: 0.98 | E23: 0.98 | F23: 0.98 | G23: 0.98 | H23: 0.98 | I23: 0.98 | J23: 0.98 | K23: 0.98
A24: Benin | B24: BEN | C24: 0.96 | E24: 0.97 | F24: 0.97 | G24: 0.96 | H24: 0.97 | I24: 0.97 | J24: 0.97 | K24: 0.97
A25: Bermuda | B25: BMU
A26: Bhutan | B26: BTN | C26: 0.97 | D26: 0.97 | E26: 0.97 | F26: 0.97 | G26: 0.96 | H26: 0.96 | I26: 0.96 | J26: 0.96 | K26: 0.96
A27: Bolivia (Plurinational State of) | B27: BOL | C27: 0.97 | D27: 0.98 | E27: 0.98 | F27: 0.98 | G27: 0.98 | H27: 0.98 | I27: 0.98 | J27: 0.96 | K27: 0.96
A28: Bonaire, Sint Eustatius and Saba | B28: BES
A29: Bosnia and Herzegovina | B29: BIH | F29: 0.97 | G29: 0.98 | H29: 0.98 | I29: 0.98 | J29: 0.97 | K29: 0.98
A30: Botswana | B30: BWA | C30: 0.95 | D30: 0.97 | E30: 0.97 | F30: 0.97 | G30: 0.98 | H30: 0.98 | I30: 0.98 | J30: 0.98 | K30: 0.98
A31: Brazil | B31: BRA | C31: 0.98 | D31: 0.98 | E31: 0.98 | F31: 0.98 | G31: 0.98 | H31: 0.98 | I31: 0.98 | J31: 0.98 | K31: 0.98
A32: British Virgin Islands | B32: VGB
A33: Brunei Darussalam | B33: BRN | C33: 0.97 | D33: 0.97 | E33: 0.97 | F33: 0.97 | G33: 0.97 | H33: 0.97 | I33: 0.97 | J33: 0.96 | K33: 0.97
A34: Bulgaria | B34: BGR | C34: 0.98 | D34: 0.98 | E34: 0.98 | F34: 0.98 | G34: 0.98 | H34: 0.98 | I34: 0.98 | J34: 0.98 | K34: 0.98
A35: Burkina Faso | B35: BFA | C35: 0.97 | D35: 0.97 | E35: 0.97 | F35: 0.97 | G35: 0.96 | H35: 0.96 | I35: 0.96 | J35: 0.98 | K35: 0.98
A36: Burundi | B36: BDI | C36: 0.97 | D36: 0.98 | E36: 0.97 | F36: 0.97 | G36: 0.98 | H36: 0.98 | I36: 0.98 | J36: 0.98 | K36: 0.98
A37: Cabo Verde | B37: CPV | C37: 0.98 | D37: 0.98 | E37: 0.98 | F37: 0.98 | G37: 0.97 | H37: 0.97 | I37: 0.97 | J37: 0.98 | K37: 0.97
A38: Cambodia | B38: KHM | C38: 0.98 | D38: 0.98 | E38: 0.98 | F38: 0.98 | G38: 0.98 | H38: 0.98 | I38: 0.98 | J38: 0.98 | K38: 0.98
A39: Cameroon | B39: CMR | C39: 0.96 | E39: 0.97 | F39: 0.97 | G39: 0.97 | H39: 0.97 | I39: 0.97 | J39: 0.97 | K39: 0.98
A40: Canada | B40: CAN | C40: 0.98 | D40: 0.97 | E40: 0.97 | F40: 0.97 | G40: 0.97 | H40: 0.97 | I40: 0.97 | J40: 0.97 | K40: 0.97
...

Sheet Religious Freedom
C1: Government Restriction Index
A2: COUNTRY | B2: ISO CODE | C2: GRI 2013 | D2: GRI 2014 | E2: GRI 2015 | F2: GRI 2016 | G2: GRI 2017 | H2: GRI 2018 | I2: GRI 2019 | J2: GRI 2020 | K2: GRI 2021
A3: Afghanistan | B3: AFG | C3: 8 | D3: 6.5 | E3: 5.5 | F3: 6 | G3: 6.5 | H3: 6.5 | I3: 6.3 | J3: 6.8 | K3: 8.2
A4: Albania | B4: ALB | C4: 2.2 | D4: 1 | E4: 2.5 | F4: 1.1 | G4: 1.6 | H4: 2.4 | I4: 1.9 | J4: 1.9 | K4: 1.9
A5: Algeria | B5: DZA | C5: 6.1 | D5: 5.8 | E5: 7.2 | F5: 7.8 | G5: 8 | H5: 8 | I5: 8 | J5: 8.4 | K5: 8.1
A6: Andorra | B6: AND | C6: 1.2 | D6: 0.9 | E6: 2.3 | F6: 2.3 | G6: 2.4 | H6: 2.4 | I6: 2.4 | J6: 2.4 | K6: 2.5
A7: Angola | B7: AGO | C7: 5 | D7: 2.7 | E7: 4.3 | F7: 4.2 | G7: 4.1 | H7: 4.3 | I7: 4.3 | J7: 2.8 | K7: 3.1
A8: Antigua and Barbuda | B8: ATG | C8: 2.3 | D8: 1.9 | E8: 2.4 | F8: 2.7 | G8: 2.2 | H8: 1.3 | I8: 0.8 | J8: 0.8 | K8: 0.8
A9: Argentina | B9: ARG | C9: 2 | D9: 2.5 | E9: 2.6 | F9: 2.6 | G9: 2.7 | H9: 2.3 | I9: 2.1 | J9: 2.2 | K9: 2.7
A10: Armenia | B10: ARM | C10: 5.2 | D10: 4.5 | E10: 3.8 | F10: 3.8 | G10: 3.7 | H10: 4.8 | I10: 3.5 | J10: 3.7 | K10: 3.7
A11: Australia | B11: AUS | C11: 1.4 | D11: 1 | E11: 1.1 | F11: 1.2 | G11: 1.1 | H11: 1.8 | I11: 1.1 | J11: 1.9 | K11: 1.6
A12: Austria | B12: AUT | C12: 3.1 | D12: 3.4 | E12: 4.1 | F12: 3.9 | G12: 4.2 | H12: 4.3 | I12: 4.4 | J12: 4.5 | K12: 4.6
A13: Azerbaijan | B13: AZE | C13: 7.3 | D13: 7.5 | E13: 6.8 | F13: 6.9 | G13: 6.8 | H13: 6.9 | I13: 7 | J13: 7 | K13: 6.7
A14: Bahamas | B14: BHS | C14: 3 | D14: 3.6 | E14: 3.6 | F14: 3 | G14: 3 | H14: 3.1 | I14: 3.4 | J14: 3.4 | K14: 3.4
... A200: Zimbabwe | B200: ZWE | C200: 2.8 | D200: 3.4 | E200: 2.8 | F200: 2.7 | G200: 2.8 | H200: 3 | I200: 3.6 | J200: 2.5 | K200: 2.1
A202: Count | C202: 198 | D202: 198 | E202: 198 | F202: 198 | G202: 198 | H202: 198 | I202: 198 | J202: 198 | K202: 198

Sheet Consolidated
C1: Positive | D1: Negative | E1: Negative | F1: Negative | G1: Positive | H1: Positive | I1: Negative
C2: 2022 | D2: 2021 | E2: 2022 | F2: 2023 | G2: 2022 | H2: 2022 | I2: 2021
A3: Country Name | B3: ISO | C3: Water | D3: Food | E3: Housing | F3: Employment | G3: Education | H3: Gender | I3: Religious Freedom
A4: Afghanistan | B4: AFG | C4: =IF(COUNT(VLOOKUP($B4,Water!$B$2:$L$235,11,FALSE)&"")=1,(VLOOKUP($B4,Water!$B$2:$L$235,11,FALSE)),"") | D4: =IF(COUNT(VLOOKUP($B4,Food!$B$2:$K$236,10,FALSE)&"")=1,VLOOKUP($B4,Food!$B$2:$K$236,10,FALSE),"") | E4: =IF(COUNT(VLOOKUP($B4,Housing!$B$2:$L$236,11,FALSE)&"")=1,VLOOKUP($B4,Housing!$B$2:$L$236,11,FALSE),"") | F4: =IF(COUNT(VLOOKUP($B4,Employment!$B$2:$M$236,12,FALSE)&"")=1,VLOOKUP($B4,Employment!$B$2:$M$236,12,FALSE),"") | G4: =IF(COUNT(VLOOKUP($B4,Education!$B$2:$L$236,11,FALSE)&"")=1,VLOOKUP($B4,Education!$B$2:$L$236,11,FALSE),"") | H4: =IF(COUNT(VLOOKUP($B4,Gender!$B$2:$K$236,10,FALSE)&"")=1,VLOOKUP($B4,Gender!$B$2:$K$236,10,FALSE),"") | I4: =IF(COUNT(VLOOKUP($B4,'Religious Freedom'!$B$2:$K$200,10,FALSE)&"")=1,VLOOKUP($B4,'Religious Freedom'!$B$2:$K$200,10,FALSE),"")
A5: Albania | B5: ALB | C5: =IF(COUNT(VLOOKUP($B5,Water!$B$2:$L$235,11,FALSE)&"")=1,(VLOOKUP($B5,Water!$B$2:$L$235,11,FALSE)),"") | D5: =IF(COUNT(VLOOKUP($B5,Food!$B$2:$K$236,10,FALSE)&"")=1,VLOOKUP($B5,Food!$B$2:$K$236,10,FALSE),"") | E5: =IF(COUNT(VLOOKUP($B5,Housing!$B$2:$L$236,11,FALSE)&"")=1,VLOOKUP($B5,Housing!$B$2:$L$236,11,FALSE),"") | F5: =IF(COUNT(VLOOKUP($B5,Employment!$B$2:$M$236,12,FALSE)&"")=1,VLOOKUP($B5,Employment!$B$2:$M$236,12,FALSE),"") | G5: =IF(COUNT(VLOOKUP($B5,Education!$B$2:$L$236,11,FALSE)&"")=1,VLOOKUP($B5,Education!$B$2:$L$236,11,FALSE),"") | H5: =IF(COUNT(VLOOKUP($B5,Gender!$B$2:$K$236,10,FALSE)&"")=1,VLOOKUP($B5,Gender!$B$2:$K$236,10,FALSE),"") | I5: =IF(COUNT(VLOOKUP($B5,'Religious Freedom'!$B$2:$K$200,10,FALSE)&"")=1,VLOOKUP($B5,'Religious Freedom'!$B$2:$K$200,10,FALSE),"")
A6: Algeria | B6: DZA | C6: =IF(COUNT(VLOOKUP($B6,Water!$B$2:$L$235,11,FALSE)&"")=1,(VLOOKUP($B6,Water!$B$2:$L$235,11,FALSE)),"") | D6: =IF(COUNT(VLOOKUP($B6,Food!$B$2:$K$236,10,FALSE)&"")=1,VLOOKUP($B6,Food!$B$2:$K$236,10,FALSE),"") | E6: =IF(COUNT(VLOOKUP($B6,Housing!$B$2:$L$236,11,FALSE)&"")=1,VLOOKUP($B6,Housing!$B$2:$L$236,11,FALSE),"") | F6: =IF(COUNT(VLOOKUP($B6,Employment!$B$2:$M$236,12,FALSE)&"")=1,VLOOKUP($B6,Employment!$B$2:$M$236,12,FALSE),"") | G6: =IF(COUNT(VLOOKUP($B6,Education!$B$2:$L$236,11,FALSE)&"")=1,VLOOKUP($B6,Education!$B$2:$L$236,11,FALSE),"") | H6: =IF(COUNT(VLOOKUP($B6,Gender!$B$2:$K$236,10,FALSE)&"")=1,VLOOKUP($B6,Gender!$B$2:$K$236,10,FALSE),"") | I6: =IF(COUNT(VLOOKUP($B6,'Religious Freedom'!$B$2:$K$200,10,FALSE)&"")=1,VLOOKUP($B6,'Religious Freedom'!$B$2:$K$200,10,FALSE),"")
A7: American Samoa | B7: ASM | C7: =IF(COUNT(VLOOKUP($B7,Water!$B$2:$L$235,11,FALSE)&"")=1,(VLOOKUP($B7,Water!$B$2:$L$235,11,FALSE)),"") | D7: =IF(COUNT(VLOOKUP($B7,Food!$B$2:$K$236,10,FALSE)&"")=1,VLOOKUP($B7,Food!$B$2:$K$236,10,FALSE),"") | E7: =IF(COUNT(VLOOKUP($B7,Housing!$B$2:$L$236,11,FALSE)&"")=1,VLOOKUP($B7,Housing!$B$2:$L$236,11,FALSE),"") | F7: =IF(COUNT(VLOOKUP($B7,Employment!$B$2:$M$236,12,FALSE)&"")=1,VLOOKUP($B7,Employment!$B$2:$M$236,12,FALSE),"") | G7: =IF(COUNT(VLOOKUP($B7,Education!$B$2:$L$236,11,FALSE)&"")=1,VLOOKUP($B7,Education!$B$2:$L$236,11,FALSE),"") | H7: =IF(COUNT(VLOOKUP($B7,Gender!$B$2:$K$236,10,FALSE)&"")=1,VLOOKUP($B7,Gender!$B$2:$K$236,10,FALSE),"") | I7: =IF(COUNT(VLOOKUP($B7,'Religious Freedom'!$B$2:$K$200,10,FALSE)&"")=1,VLOOKUP($B7,'Religious Freedom'!$B$2:$K$200,10,FALSE),"")
A8: Andorra | B8: AND | C8: =IF(COUNT(VLOOKUP($B8,Water!$B$2:$L$235,11,FALSE)&"")=1,(VLOOKUP($B8,Water!$B$2:$L$235,11,FALSE)),"") | D8: =IF(COUNT(VLOOKUP($B8,Food!$B$2:$K$236,10,FALSE)&"")=1,VLOOKUP($B8,Food!$B$2:$K$236,10,FALSE),"") | E8: =IF(COUNT(VLOOKUP($B8,Housing!$B$2:$L$236,11,FALSE)&"")=1,VLOOKUP($B8,Housing!$B$2:$L$236,11,FALSE),"") | F8: =IF(COUNT(VLOOKUP($B8,Employment!$B$2:$M$236,12,FALSE)&"")=1,VLOOKUP($B8,Employment!$B$2:$M$236,12,FALSE),"") | G8: =IF(COUNT(VLOOKUP($B8,Education!$B$2:$L$236,11,FALSE)&"")=1,VLOOKUP($B8,Education!$B$2:$L$236,11,FALSE),"") | H8: =IF(COUNT(VLOOKUP($B8,Gender!$B$2:$K$236,10,FALSE)&"")=1,VLOOKUP($B8,Gender!$B$2:$K$236,10,FALSE),"") | I8: =IF(COUNT(VLOOKUP($B8,'Religious Freedom'!$B$2:$K$200,10,FALSE)&"")=1,VLOOKUP($B8,'Religious Freedom'!$B$2:$K$200,10,FALSE),"")
A9: Angola | B9: AGO | C9: =IF(COUNT(VLOOKUP($B9,Water!$B$2:$L$235,11,FALSE)&"")=1,(VLOOKUP($B9,Water!$B$2:$L$235,11,FALSE)),"") | D9: =IF(COUNT(VLOOKUP($B9,Food!$B$2:$K$236,10,FALSE)&"")=1,VLOOKUP($B9,Food!$B$2:$K$236,10,FALSE),"") | E9: =IF(COUNT(VLOOKUP($B9,Housing!$B$2:$L$236,11,FALSE)&"")=1,VLOOKUP($B9,Housing!$B$2:$L$236,11,FALSE),"") | F9: =IF(COUNT(VLOOKUP($B9,Employment!$B$2:$M$236,12,FALSE)&"")=1,VLOOKUP($B9,Employment!$B$2:$M$236,12,FALSE),"") | G9: =IF(COUNT(VLOOKUP($B9,Education!$B$2:$L$236,11,FALSE)&"")=1,VLOOKUP($B9,Education!$B$2:$L$236,11,FALSE),"") | H9: =IF(COUNT(VLOOKUP($B9,Gender!$B$2:$K$236,10,FALSE)&"")=1,VLOOKUP($B9,Gender!$B$2:$K$236,10,FALSE),"") | I9: =IF(COUNT(VLOOKUP($B9,'Religious Freedom'!$B$2:$K$200,10,FALSE)&"")=1,VLOOKUP($B9,'Religious Freedom'!$B$2:$K$200,10,FALSE),"")
A10: Anguilla | B10: AIA | C10: =IF(COUNT(VLOOKUP($B10,Water!$B$2:$L$235,11,FALSE)&"")=1,(VLOOKUP($B10,Water!$B$2:$L$235,11,FALSE)),"") | D10: =IF(COUNT(VLOOKUP($B10,Food!$B$2:$K$236,10,FALSE)&"")=1,VLOOKUP($B10,Food!$B$2:$K$236,10,FALSE),"") | E10: =IF(COUNT(VLOOKUP($B10,Housing!$B$2:$L$236,11,FALSE)&"")=1,VLOOKUP($B10,Housing!$B$2:$L$236,11,FALSE),"") | F10: =IF(COUNT(VLOOKUP($B10,Employment!$B$2:$M$236,12,FALSE)&"")=1,VLOOKUP($B10,Employment!$B$2:$M$236,12,FALSE),"") | G10: =IF(COUNT(VLOOKUP($B10,Education!$B$2:$L$236,11,FALSE)&"")=1,VLOOKUP($B10,Education!$B$2:$L$236,11,FALSE),"") | H10: =IF(COUNT(VLOOKUP($B10,Gender!$B$2:$K$236,10,FALSE)&"")=1,VLOOKUP($B10,Gender!$B$2:$K$236,10,FALSE),"") | I10: =IF(COUNT(VLOOKUP($B10,'Religious Freedom'!$B$2:$K$200,10,FALSE)&"")=1,VLOOKUP($B10,'Religious Freedom'!$B$2:$K$200,10,FALSE),"")
A11: Antigua and Barbuda | B11: ATG | C11: =IF(COUNT(VLOOKUP($B11,Water!$B$2:$L$235,11,FALSE)&"")=1,(VLOOKUP($B11,Water!$B$2:$L$235,11,FALSE)),"") | D11: =IF(COUNT(VLOOKUP($B11,Food!$B$2:$K$236,10,FALSE)&"")=1,VLOOKUP($B11,Food!$B$2:$K$236,10,FALSE),"") | E11: =IF(COUNT(VLOOKUP($B11,Housing!$B$2:$L$236,11,FALSE)&"")=1,VLOOKUP($B11,Housing!$B$2:$L$236,11,FALSE),"") | F11: =IF(COUNT(VLOOKUP($B11,Employment!$B$2:$M$236,12,FALSE)&"")=1,VLOOKUP($B11,Employment!$B$2:$M$236,12,FALSE),"") | G11: =IF(COUNT(VLOOKUP($B11,Education!$B$2:$L$236,11,FALSE)&"")=1,VLOOKUP($B11,Education!$B$2:$L$236,11,FALSE),"") | H11: =IF(COUNT(VLOOKUP($B11,Gender!$B$2:$K$236,10,FALSE)&"")=1,VLOOKUP($B11,Gender!$B$2:$K$236,10,FALSE),"") | I11: =IF(COUNT(VLOOKUP($B11,'Religious Freedom'!$B$2:$K$200,10,FALSE)&"")=1,VLOOKUP($B11,'Religious Freedom'!$B$2:$K$200,10,FALSE),"")
A12: Argentina | B12: ARG | C12: =IF(COUNT(VLOOKUP($B12,Water!$B$2:$L$235,11,FALSE)&"")=1,(VLOOKUP($B12,Water!$B$2:$L$235,11,FALSE)),"") | D12: =IF(COUNT(VLOOKUP($B12,Food!$B$2:$K$236,10,FALSE)&"")=1,VLOOKUP($B12,Food!$B$2:$K$236,10,FALSE),"") | E12: =IF(COUNT(VLOOKUP($B12,Housing!$B$2:$L$236,11,FALSE)&"")=1,VLOOKUP($B12,Housing!$B$2:$L$236,11,FALSE),"") | F12: =IF(COUNT(VLOOKUP($B12,Employment!$B$2:$M$236,12,FALSE)&"")=1,VLOOKUP($B12,Employment!$B$2:$M$236,12,FALSE),"") | G12: =IF(COUNT(VLOOKUP($B12,Education!$B$2:$L$236,11,FALSE)&"")=1,VLOOKUP($B12,Education!$B$2:$L$236,11,FALSE),"") | H12: =IF(COUNT(VLOOKUP($B12,Gender!$B$2:$K$236,10,FALSE)&"")=1,VLOOKUP($B12,Gender!$B$2:$K$236,10,FALSE),"") | I12: =IF(COUNT(VLOOKUP($B12,'Religious Freedom'!$B$2:$K$200,10,FALSE)&"")=1,VLOOKUP($B12,'Religious Freedom'!$B$2:$K$200,10,FALSE),"")
A13: Armenia | B13: ARM | C13: =IF(COUNT(VLOOKUP($B13,Water!$B$2:$L$235,11,FALSE)&"")=1,(VLOOKUP($B13,Water!$B$2:$L$235,11,FALSE)),"") | D13: =IF(COUNT(VLOOKUP($B13,Food!$B$2:$K$236,10,FALSE)&"")=1,VLOOKUP($B13,Food!$B$2:$K$236,10,FALSE),"") | E13: =IF(COUNT(VLOOKUP($B13,Housing!$B$2:$L$236,11,FALSE)&"")=1,VLOOKUP($B13,Housing!$B$2:$L$236,11,FALSE),"") | F13: =IF(COUNT(VLOOKUP($B13,Employment!$B$2:$M$236,12,FALSE)&"")=1,VLOOKUP($B13,Employment!$B$2:$M$236,12,FALSE),"") | G13: =IF(COUNT(VLOOKUP($B13,Education!$B$2:$L$236,11,FALSE)&"")=1,VLOOKUP($B13,Education!$B$2:$L$236,11,FALSE),"") | H13: =IF(COUNT(VLOOKUP($B13,Gender!$B$2:$K$236,10,FALSE)&"")=1,VLOOKUP($B13,Gender!$B$2:$K$236,10,FALSE),"") | I13: =IF(COUNT(VLOOKUP($B13,'Religious Freedom'!$B$2:$K$200,10,FALSE)&"")=1,VLOOKUP($B13,'Religious Freedom'!$B$2:$K$200,10,FALSE),"")
A14: Aruba | B14: ABW | C14: =IF(COUNT(VLOOKUP($B14,Water!$B$2:$L$235,11,FALSE)&"")=1,(VLOOKUP($B14,Water!$B$2:$L$235,11,FALSE)),"") | D14: =IF(COUNT(VLOOKUP($B14,Food!$B$2:$K$236,10,FALSE)&"")=1,VLOOKUP($B14,Food!$B$2:$K$236,10,FALSE),"") | E14: =IF(COUNT(VLOOKUP($B14,Housing!$B$2:$L$236,11,FALSE)&"")=1,VLOOKUP($B14,Housing!$B$2:$L$236,11,FALSE),"") | F14: =IF(COUNT(VLOOKUP($B14,Employment!$B$2:$M$236,12,FALSE)&"")=1,VLOOKUP($B14,Employment!$B$2:$M$236,12,FALSE),"") | G14: =IF(COUNT(VLOOKUP($B14,Education!$B$2:$L$236,11,FALSE)&"")=1,VLOOKUP($B14,Education!$B$2:$L$236,11,FALSE),"") | H14: =IF(COUNT(VLOOKUP($B14,Gender!$B$2:$K$236,10,FALSE)&"")=1,VLOOKUP($B14,Gender!$B$2:$K$236,10,FALSE),"") | I14: =IF(COUNT(VLOOKUP($B14,'Religious Freedom'!$B$2:$K$200,10,FALSE)&"")=1,VLOOKUP($B14,'Religious Freedom'!$B$2:$K$200,10,FALSE),"")
A15: Australia | B15: AUS | C15: =IF(COUNT(VLOOKUP($B15,Water!$B$2:$L$235,11,FALSE)&"")=1,(VLOOKUP($B15,Water!$B$2:$L$235,11,FALSE)),"") | D15: =IF(COUNT(VLOOKUP($B15,Food!$B$2:$K$236,10,FALSE)&"")=1,VLOOKUP($B15,Food!$B$2:$K$236,10,FALSE),"") | E15: =IF(COUNT(VLOOKUP($B15,Housing!$B$2:$L$236,11,FALSE)&"")=1,VLOOKUP($B15,Housing!$B$2:$L$236,11,FALSE),"") | F15: =IF(COUNT(VLOOKUP($B15,Employment!$B$2:$M$236,12,FALSE)&"")=1,VLOOKUP($B15,Employment!$B$2:$M$236,12,FALSE),"") | G15: =IF(COUNT(VLOOKUP($B15,Education!$B$2:$L$236,11,FALSE)&"")=1,VLOOKUP($B15,Education!$B$2:$L$236,11,FALSE),"") | H15: =IF(COUNT(VLOOKUP($B15,Gender!$B$2:$K$236,10,FALSE)&"")=1,VLOOKUP($B15,Gender!$B$2:$K$236,10,FALSE),"") | I15: =IF(COUNT(VLOOKUP($B15,'Religious Freedom'!$B$2:$K$200,10,FALSE)&"")=1,VLOOKUP($B15,'Religious Freedom'!$B$2:$K$200,10,FALSE),"")
... A117: Kyrgyzstan | B117: KGZ | C117: =IF(COUNT(VLOOKUP($B117,Water!$B$2:$L$235,11,FALSE)&"")=1,(VLOOKUP($B117,Water!$B$2:$L$235,11,FALSE)),"") | D117: =IF(COUNT(VLOOKUP($B117,Food!$B$2:$K$236,10,FALSE)&"")=1,VLOOKUP($B117,Food!$B$2:$K$236,10,FALSE),"") | E117: =IF(COUNT(VLOOKUP($B117,Housing!$B$2:$L$236,11,FALSE)&"")=1,VLOOKUP($B117,Housing!$B$2:$L$236,11,FALSE),"") | F117: =IF(COUNT(VLOOKUP($B117,Employment!$B$2:$M$236,12,FALSE)&"")=1,VLOOKUP($B117,Employment!$B$2:$M$236,12,FALSE),"") | G117: =IF(COUNT(VLOOKUP($B117,Education!$B$2:$L$236,11,FALSE)&"")=1,VLOOKUP($B117,Education!$B$2:$L$236,11,FALSE),"") | H117: =IF(COUNT(VLOOKUP($B117,Gender!$B$2:$K$236,10,FALSE)&"")=1,VLOOKUP($B117,Gender!$B$2:$K$236,10,FALSE),"") | I117: =IF(COUNT(VLOOKUP($B117,'Religious Freedom'!$B$2:$K$200,10,FALSE)&"")=1,VLOOKUP($B117,'Religious Freedom'!$B$2:$K$200,10,FALSE),"")
A118: Kosovo | B118: XKX | I118: =IF(COUNT(VLOOKUP($B118,'Religious Freedom'!$B$2:$K$200,10,FALSE)&"")=1,VLOOKUP($B118,'Religious Freedom'!$B$2:$K$200,10,FALSE),"")
A119: Lao People's Democratic Republic | B119: LAO | C119: =IF(COUNT(VLOOKUP($B119,Water!$B$2:$L$235,11,FALSE)&"")=1,(VLOOKUP($B119,Water!$B$2:$L$235,11,FALSE)),"") | D119: =IF(COUNT(VLOOKUP($B119,Food!$B$2:$K$236,10,FALSE)&"")=1,VLOOKUP($B119,Food!$B$2:$K$236,10,FALSE),"") | E119: =IF(COUNT(VLOOKUP($B119,Housing!$B$2:$L$236,11,FALSE)&"")=1,VLOOKUP($B119,Housing!$B$2:$L$236,11,FALSE),"") | F119: =IF(COUNT(VLOOKUP($B119,Employment!$B$2:$M$236,12,FALSE)&"")=1,VLOOKUP($B119,Employment!$B$2:$M$236,12,FALSE),"") | G119: =IF(COUNT(VLOOKUP($B119,Education!$B$2:$L$236,11,FALSE)&"")=1,VLOOKUP($B119,Education!$B$2:$L$236,11,FALSE),"") | H119: =IF(COUNT(VLOOKUP($B119,Gender!$B$2:$K$236,10,FALSE)&"")=1,VLOOKUP($B119,Gender!$B$2:$K$236,10,FALSE),"") | I119: =IF(COUNT(VLOOKUP($B119,'Religious Freedom'!$B$2:$K$200,10,FALSE)&"")=1,VLOOKUP($B119,'Religious Freedom'!$B$2:$K$200,10,FALSE),"")
A120: Latvia | B120: LVA | C120: =IF(COUNT(VLOOKUP($B120,Water!$B$2:$L$235,11,FALSE)&"")=1,(VLOOKUP($B120,Water!$B$2:$L$235,11,FALSE)),"") | D120: =IF(COUNT(VLOOKUP($B120,Food!$B$2:$K$236,10,FALSE)&"")=1,VLOOKUP($B120,Food!$B$2:$K$236,10,FALSE),"") | E120: =IF(COUNT(VLOOKUP($B120,Housing!$B$2:$L$236,11,FALSE)&"")=1,VLOOKUP($B120,Housing!$B$2:$L$236,11,FALSE),"") | F120: =IF(COUNT(VLOOKUP($B120,Employment!$B$2:$M$236,12,FALSE)&"")=1,VLOOKUP($B120,Employment!$B$2:$M$236,12,FALSE),"") | G120: =IF(COUNT(VLOOKUP($B120,Education!$B$2:$L$236,11,FALSE)&"")=1,VLOOKUP($B120,Education!$B$2:$L$236,11,FALSE),"") | H120: =IF(COUNT(VLOOKUP($B120,Gender!$B$2:$K$236,10,FALSE)&"")=1,VLOOKUP($B120,Gender!$B$2:$K$236,10,FALSE),"") | I120: =IF(COUNT(VLOOKUP($B120,'Religious Freedom'!$B$2:$K$200,10,FALSE)&"")=1,VLOOKUP($B120,'Religious Freedom'!$B$2:$K$200,10,FALSE),"")
A121: Lebanon | B121: LBN | C121: =IF(COUNT(VLOOKUP($B121,Water!$B$2:$L$235,11,FALSE)&"")=1,(VLOOKUP($B121,Water!$B$2:$L$235,11,FALSE)),"") | D121: =IF(COUNT(VLOOKUP($B121,Food!$B$2:$K$236,10,FALSE)&"")=1,VLOOKUP($B121,Food!$B$2:$K$236,10,FALSE),"") | E121: =IF(COUNT(VLOOKUP($B121,Housing!$B$2:$L$236,11,FALSE)&"")=1,VLOOKUP($B121,Housing!$B$2:$L$236,11,FALSE),"") | F121: =IF(COUNT(VLOOKUP($B121,Employment!$B$2:$M$236,12,FALSE)&"")=1,VLOOKUP($B121,Employment!$B$2:$M$236,12,FALSE),"") | G121: =IF(COUNT(VLOOKUP($B121,Education!$B$2:$L$236,11,FALSE)&"")=1,VLOOKUP($B121,Education!$B$2:$L$236,11,FALSE),"") | H121: =IF(COUNT(VLOOKUP($B121,Gender!$B$2:$K$236,10,FALSE)&"")=1,VLOOKUP($B121,Gender!$B$2:$K$236,10,FALSE),"") | I121: =IF(COUNT(VLOOKUP($B121,'Religious Freedom'!$B$2:$K$200,10,FALSE)&"")=1,VLOOKUP($B121,'Religious Freedom'!$B$2:$K$200,10,FALSE),"")
A122: Lesotho | B122: LSO | C122: =IF(COUNT(VLOOKUP($B122,Water!$B$2:$L$235,11,FALSE)&"")=1,(VLOOKUP($B122,Water!$B$2:$L$235,11,FALSE)),"") | D122: =IF(COUNT(VLOOKUP($B122,Food!$B$2:$K$236,10,FALSE)&"")=1,VLOOKUP($B122,Food!$B$2:$K$236,10,FALSE),"") | E122: =IF(COUNT(VLOOKUP($B122,Housing!$B$2:$L$236,11,FALSE)&"")=1,VLOOKUP($B122,Housing!$B$2:$L$236,11,FALSE),"") | F122: =IF(COUNT(VLOOKUP($B122,Employment!$B$2:$M$236,12,FALSE)&"")=1,VLOOKUP($B122,Employment!$B$2:$M$236,12,FALSE),"") | G122: =IF(COUNT(VLOOKUP($B122,Education!$B$2:$L$236,11,FALSE)&"")=1,VLOOKUP($B122,Education!$B$2:$L$236,11,FALSE),"") | H122: =IF(COUNT(VLOOKUP($B122,Gender!$B$2:$K$236,10,FALSE)&"")=1,VLOOKUP($B122,Gender!$B$2:$K$236,10,FALSE),"") | I122: =IF(COUNT(VLOOKUP($B122,'Religious Freedom'!$B$2:$K$200,10,FALSE)&"")=1,VLOOKUP($B122,'Religious Freedom'!$B$2:$K$200,10,FALSE),"")
A123: Liberia | B123: LBR | C123: =IF(COUNT(VLOOKUP($B123,Water!$B$2:$L$235,11,FALSE)&"")=1,(VLOOKUP($B123,Water!$B$2:$L$235,11,FALSE)),"") | D123: =IF(COUNT(VLOOKUP($B123,Food!$B$2:$K$236,10,FALSE)&"")=1,VLOOKUP($B123,Food!$B$2:$K$236,10,FALSE),"") | E123: =IF(COUNT(VLOOKUP($B123,Housing!$B$2:$L$236,11,FALSE)&"")=1,VLOOKUP($B123,Housing!$B$2:$L$236,11,FALSE),"") | F123: =IF(COUNT(VLOOKUP($B123,Employment!$B$2:$M$236,12,FALSE)&"")=1,VLOOKUP($B123,Employment!$B$2:$M$236,12,FALSE),"") | G123: =IF(COUNT(VLOOKUP($B123,Education!$B$2:$L$236,11,FALSE)&"")=1,VLOOKUP($B123,Education!$B$2:$L$236,11,FALSE),"") | H123: =IF(COUNT(VLOOKUP($B123,Gender!$B$2:$K$236,10,FALSE)&"")=1,VLOOKUP($B123,Gender!$B$2:$K$236,10,FALSE),"") | I123: =IF(COUNT(VLOOKUP($B123,'Religious Freedom'!$B$2:$K$200,10,FALSE)&"")=1,VLOOKUP($B123,'Religious Freedom'!$B$2:$K$200,10,FALSE),"")
A124: Libya | B124: LBY | C124: =IF(COUNT(VLOOKUP($B124,Water!$B$2:$L$235,11,FALSE)&"")=1,(VLOOKUP($B124,Water!$B$2:$L$235,11,FALSE)),"") | D124: =IF(COUNT(VLOOKUP($B124,Food!$B$2:$K$236,10,FALSE)&"")=1,VLOOKUP($B124,Food!$B$2:$K$236,10,FALSE),"") | E124: =IF(COUNT(VLOOKUP($B124,Housing!$B$2:$L$236,11,FALSE)&"")=1,VLOOKUP($B124,Housing!$B$2:$L$236,11,FALSE),"") | F124: =IF(COUNT(VLOOKUP($B124,Employment!$B$2:$M$236,12,FALSE)&"")=1,VLOOKUP($B124,Employment!$B$2:$M$236,12,FALSE),"") | G124: =IF(COUNT(VLOOKUP($B124,Education!$B$2:$L$236,11,FALSE)&"")=1,VLOOKUP($B124,Education!$B$2:$L$236,11,FALSE),"") | H124: =IF(COUNT(VLOOKUP($B124,Gender!$B$2:$K$236,10,FALSE)&"")=1,VLOOKUP($B124,Gender!$B$2:$K$236,10,FALSE),"") | I124: =IF(COUNT(VLOOKUP($B124,'Religious Freedom'!$B$2:$K$200,10,FALSE)&"")=1,VLOOKUP($B124,'Religious Freedom'!$B$2:$K$200,10,FALSE),"")
A125: Liechtenstein | B125: LIE | C125: =IF(COUNT(VLOOKUP($B125,Water!$B$2:$L$235,11,FALSE)&"")=1,(VLOOKUP($B125,Water!$B$2:$L$235,11,FALSE)),"") | D125: =IF(COUNT(VLOOKUP($B125,Food!$B$2:$K$236,10,FALSE)&"")=1,VLOOKUP($B125,Food!$B$2:$K$236,10,FALSE),"") | E125: =IF(COUNT(VLOOKUP($B125,Housing!$B$2:$L$236,11,FALSE)&"")=1,VLOOKUP($B125,Housing!$B$2:$L$236,11,FALSE),"") | F125: =IF(COUNT(VLOOKUP($B125,Employment!$B$2:$M$236,12,FALSE)&"")=1,VLOOKUP($B125,Employment!$B$2:$M$236,12,FALSE),"") | G125: =IF(COUNT(VLOOKUP($B125,Education!$B$2:$L$236,11,FALSE)&"")=1,VLOOKUP($B125,Education!$B$2:$L$236,11,FALSE),"") | H125: =IF(COUNT(VLOOKUP($B125,Gender!$B$2:$K$236,10,FALSE)&"")=1,VLOOKUP($B125,Gender!$B$2:$K$236,10,FALSE),"") | I125: =IF(COUNT(VLOOKUP($B125,'Religious Freedom'!$B$2:$K$200,10,FALSE)&"")=1,VLOOKUP($B125,'Religious Freedom'!$B$2:$K$200,10,FALSE),"")
A126: Lithuania | B126: LTU | C126: =IF(COUNT(VLOOKUP($B126,Water!$B$2:$L$235,11,FALSE)&"")=1,(VLOOKUP($B126,Water!$B$2:$L$235,11,FALSE)),"") | D126: =IF(COUNT(VLOOKUP($B126,Food!$B$2:$K$236,10,FALSE)&"")=1,VLOOKUP($B126,Food!$B$2:$K$236,10,FALSE),"") | E126: =IF(COUNT(VLOOKUP($B126,Housing!$B$2:$L$236,11,FALSE)&"")=1,VLOOKUP($B126,Housing!$B$2:$L$236,11,FALSE),"") | F126: =IF(COUNT(VLOOKUP($B126,Employment!$B$2:$M$236,12,FALSE)&"")=1,VLOOKUP($B126,Employment!$B$2:$M$236,12,FALSE),"") | G126: =IF(COUNT(VLOOKUP($B126,Education!$B$2:$L$236,11,FALSE)&"")=1,VLOOKUP($B126,Education!$B$2:$L$236,11,FALSE),"") | H126: =IF(COUNT(VLOOKUP($B126,Gender!$B$2:$K$236,10,FALSE)&"")=1,VLOOKUP($B126,Gender!$B$2:$K$236,10,FALSE),"") | I126: =IF(COUNT(VLOOKUP($B126,'Religious Freedom'!$B$2:$K$200,10,FALSE)&"")=1,VLOOKUP($B126,'Religious Freedom'!$B$2:$K$200,10,FALSE),"")
A127: Luxembourg | B127: LUX | C127: =IF(COUNT(VLOOKUP($B127,Water!$B$2:$L$235,11,FALSE)&"")=1,(VLOOKUP($B127,Water!$B$2:$L$235,11,FALSE)),"") | D127: =IF(COUNT(VLOOKUP($B127,Food!$B$2:$K$236,10,FALSE)&"")=1,VLOOKUP($B127,Food!$B$2:$K$236,10,FALSE),"") | E127: =IF(COUNT(VLOOKUP($B127,Housing!$B$2:$L$236,11,FALSE)&"")=1,VLOOKUP($B127,Housing!$B$2:$L$236,11,FALSE),"") | F127: =IF(COUNT(VLOOKUP($B127,Employment!$B$2:$M$236,12,FALSE)&"")=1,VLOOKUP($B127,Employment!$B$2:$M$236,12,FALSE),"") | G127: =IF(COUNT(VLOOKUP($B127,Education!$B$2:$L$236,11,FALSE)&"")=1,VLOOKUP($B127,Education!$B$2:$L$236,11,FALSE),"") | H127: =IF(COUNT(VLOOKUP($B127,Gender!$B$2:$K$236,10,FALSE)&"")=1,VLOOKUP($B127,Gender!$B$2:$K$236,10,FALSE),"") | I127: =IF(COUNT(VLOOKUP($B127,'Religious Freedom'!$B$2:$K$200,10,FALSE)&"")=1,VLOOKUP($B127,'Religious Freedom'!$B$2:$K$200,10,FALSE),"")
A128: Madagascar | B128: MDG | C128: =IF(COUNT(VLOOKUP($B128,Water!$B$2:$L$235,11,FALSE)&"")=1,(VLOOKUP($B128,Water!$B$2:$L$235,11,FALSE)),"") | D128: =IF(COUNT(VLOOKUP($B128,Food!$B$2:$K$236,10,FALSE)&"")=1,VLOOKUP($B128,Food!$B$2:$K$236,10,FALSE),"") | E128: =IF(COUNT(VLOOKUP($B128,Housing!$B$2:$L$236,11,FALSE)&"")=1,VLOOKUP($B128,Housing!$B$2:$L$236,11,FALSE),"") | F128: =IF(COUNT(VLOOKUP($B128,Employment!$B$2:$M$236,12,FALSE)&"")=1,VLOOKUP($B128,Employment!$B$2:$M$236,12,FALSE),"") | G128: =IF(COUNT(VLOOKUP($B128,Education!$B$2:$L$236,11,FALSE)&"")=1,VLOOKUP($B128,Education!$B$2:$L$236,11,FALSE),"") | H128: =IF(COUNT(VLOOKUP($B128,Gender!$B$2:$K$236,10,FALSE)&"")=1,VLOOKUP($B128,Gender!$B$2:$K$236,10,FALSE),"") | I128: =IF(COUNT(VLOOKUP($B128,'Religious Freedom'!$B$2:$K$200,10,FALSE)&"")=1,VLOOKUP($B128,'Religious Freedom'!$B$2:$K$200,10,FALSE),"")
A129: Malawi | B129: MWI | C129: =IF(COUNT(VLOOKUP($B129,Water!$B$2:$L$235,11,FALSE)&"")=1,(VLOOKUP($B129,Water!$B$2:$L$235,11,FALSE)),"") | D129: =IF(COUNT(VLOOKUP($B129,Food!$B$2:$K$236,10,FALSE)&"")=1,VLOOKUP($B129,Food!$B$2:$K$236,10,FALSE),"") | E129: =IF(COUNT(VLOOKUP($B129,Housing!$B$2:$L$236,11,FALSE)&"")=1,VLOOKUP($B129,Housing!$B$2:$L$236,11,FALSE),"") | F129: =IF(COUNT(VLOOKUP($B129,Employment!$B$2:$M$236,12,FALSE)&"")=1,VLOOKUP($B129,Employment!$B$2:$M$236,12,FALSE),"") | G129: =IF(COUNT(VLOOKUP($B129,Education!$B$2:$L$236,11,FALSE)&"")=1,VLOOKUP($B129,Education!$B$2:$L$236,11,FALSE),"") | H129: =IF(COUNT(VLOOKUP($B129,Gender!$B$2:$K$236,10,FALSE)&"")=1,VLOOKUP($B129,Gender!$B$2:$K$236,10,FALSE),"") | I129: =IF(COUNT(VLOOKUP($B129,'Religious Freedom'!$B$2:$K$200,10,FALSE)&"")=1,VLOOKUP($B129,'Religious Freedom'!$B$2:$K$200,10,FALSE),"")
A130: Malaysia | B130: MYS | C130: =IF(COUNT(VLOOKUP($B130,Water!$B$2:$L$235,11,FALSE)&"")=1,(VLOOKUP($B130,Water!$B$2:$L$235,11,FALSE)),"") | D130: =IF(COUNT(VLOOKUP($B130,Food!$B$2:$K$236,10,FALSE)&"")=1,VLOOKUP($B130,Food!$B$2:$K$236,10,FALSE),"") | E130: =IF(COUNT(VLOOKUP($B130,Housing!$B$2:$L$236,11,FALSE)&"")=1,VLOOKUP($B130,Housing!$B$2:$L$236,11,FALSE),"") | F130: =IF(COUNT(VLOOKUP($B130,Employment!$B$2:$M$236,12,FALSE)&"")=1,VLOOKUP($B130,Employment!$B$2:$M$236,12,FALSE),"") | G130: =IF(COUNT(VLOOKUP($B130,Education!$B$2:$L$236,11,FALSE)&"")=1,VLOOKUP($B130,Education!$B$2:$L$236,11,FALSE),"") | H130: =IF(COUNT(VLOOKUP($B130,Gender!$B$2:$K$236,10,FALSE)&"")=1,VLOOKUP($B130,Gender!$B$2:$K$236,10,FALSE),"") | I130: =IF(COUNT(VLOOKUP($B130,'Religious Freedom'!$B$2:$K$200,10,FALSE)&"")=1,VLOOKUP($B130,'Religious Freedom'!$B$2:$K$200,10,FALSE),"")
... A238: Zimbabwe | B238: ZWE | C238: =IF(COUNT(VLOOKUP($B238,Water!$B$2:$L$235,11,FALSE)&"")=1,(VLOOKUP($B238,Water!$B$2:$L$235,11,FALSE)),"") | D238: =IF(COUNT(VLOOKUP($B238,Food!$B$2:$K$236,10,FALSE)&"")=1,VLOOKUP($B238,Food!$B$2:$K$236,10,FALSE),"") | E238: =IF(COUNT(VLOOKUP($B238,Housing!$B$2:$L$236,11,FALSE)&"")=1,VLOOKUP($B238,Housing!$B$2:$L$236,11,FALSE),"") | F238: =IF(COUNT(VLOOKUP($B238,Employment!$B$2:$M$236,12,FALSE)&"")=1,VLOOKUP($B238,Employment!$B$2:$M$236,12,FALSE),"") | G238: =IF(COUNT(VLOOKUP($B238,Education!$B$2:$L$236,11,FALSE)&"")=1,VLOOKUP($B238,Education!$B$2:$L$236,11,FALSE),"") | H238: =IF(COUNT(VLOOKUP($B238,Gender!$B$2:$K$236,10,FALSE)&"")=1,VLOOKUP($B238,Gender!$B$2:$K$236,10,FALSE),"") | I238: =IF(COUNT(VLOOKUP($B238,'Religious Freedom'!$B$2:$K$200,10,FALSE)&"")=1,VLOOKUP($B238,'Religious Freedom'!$B$2:$K$200,10,FALSE),"")
A240: Count | C240: =COUNT(C4:C238) -> 0 | D240: =COUNT(D4:D238) -> 0 | E240: =COUNT(E4:E238) -> 0 | F240: =COUNT(F4:F238) -> 0 | G240: =COUNT(G4:G238) -> 0 | H240: =COUNT(H4:H238) -> 0 | I240: =COUNT(I4:I238) -> 0

Sheet Sheet2
B1: Water | C1: Food | D1: Housing | E1: Employment | F1: Education | G1: Gender | H1: Religious Freedom
A2: Water | B2: 1
A3: Food | B3: -0.7431426 | C3: 1
A4: Housing | B4: -0.81835789 | C4: 0.60142189 | D4: 1
A5: Employment | B5: -0.66642213 | C5: 0.71197239 | D5: 0.63746705 | E5: 1
A6: Education | B6: 0.73087235 | C6: -0.55669154 | D6: -0.76354711 | E6: -0.5507405 | F6: 1
A7: Gender | B7: -0.20991438 | C7: 0.05687892 | D7: -0.089267152 | E7: 0.14766496 | F7: 0.13435457 | G7: 1
A8: Religious Freedom | B8: 0.096886663 | C8: -0.12811571 | D8: -0.055359368 | E8: -0.095067794 | F8: 0.053433903 | G8: -0.35087053 | H8: 1

Sheet Sheet1
C1: Positive | D1: Negative | E1: Negative | F1: Negative | G1: Positive | H1: Positive | I1: Negative
C2: 2022 | D2: 2021 | E2: 2022 | F2: 2023 | G2: 2022 | H2: 2022 | I2: 2021
A3: Country Name | B3: ISO | C3: Water | D3: Food | E3: Housing | F3: Employment | G3: Education | H3: Gender | I3: Religious Freedom
A4: Afghanistan | B4: AFG | C4: 82.175371 | D4: 30.1 | E4: 54.479075 | F4: 0.91120363 | G4: 37.266041 | H4: 0.95 | I4: 8.2
A5: Albania | B5: ALB | C5: 95.094564 | D5: 4.1 | E5: 0.13925181 | F5: 0.1174437 | G5: 98.5 | H5: 0.96 | I5: 1.9
A6: Algeria | B6: DZA | C6: 94.661398 | D6: 2.5 | E6: 0.44245003 | F6: 0.12678003 | G6: 81.407837 | H6: 0.96 | I6: 8.1
A7: American Samoa | B7: ASM
A8: Andorra | B8: AND | C8: 99 | I8: 2.5
A9: Angola | B9: AGO | C9: 57.719561 | D9: 21.6 | E9: 44.128182 | F9: 0.59890395 | G9: 72.400002 | H9: 0.98 | I9: 3.1
A10: Anguilla | B10: AIA
A11: Antigua and Barbuda | B11: ATG | C11: 98.364936 | I11: 0.8
A12: Argentina | B12: ARG | D12: 3.2 | E12: 44.128182 | F12: 0.072126191 | H12: 0.98 | I12: 2.7
A13: Armenia | B13: ARM | C13: 99 | D13: 2.5 | E13: 0.023653369 | F13: 0.10509888 | G13: 99.788612 | H13: 0.95 | I13: 3.7
A14: Aruba | B14: ABW | G14: 97.989998
A15: Australia | B15: AUS | C15: 99 | D15: 2.5 | H15: 0.97 | I15: 1.6
A16: Austria | B16: AUT | C16: 99 | D16: 2.5 | H16: 0.97 | I16: 4.6
A17: Azerbaijan | B17: AZE | C17: 97.642187 | D17: 2.5 | F17: 0.05819199 | G17: 99.795982 | H17: 0.94 | I17: 6.7
A18: Bahamas | B18: BHS | F18: 0.093126551 | I18: 3.4
A19: Bahrain | B19: BHR | C19: 99 | F19: 0.013826776 | G19: 97.872482 | H19: 0.96 | I19: 6.5
A20: Bangladesh | B20: BGD | C20: 98.097063 | D20: 11.2 | E20: 23.329691 | F20: 0.36919423 | G20: 76.362877 | H20: 0.96 | I20: 5.1
A21: Barbados | B21: BRB | C21: 98.51445 | D21: 2.5 | E21: 0.2709889 | F21: 0.14145258 | H21: 0.97 | I21: 0.7
A22: Belarus | B22: BLR | C22: 99 | D22: 2.5 | F22: 0.037052505 | G22: 99.874001 | H22: 0.98 | I22: 6.2
A23: Belgium | B23: BEL | C23: 99 | D23: 2.5 | H23: 0.97 | I23: 3.6
A24: Belize | B24: BLZ | C24: 98.405234 | D24: 4.9 | E24: 2.8491478 | F24: 0.3282807 | H24: 0.98 | I24: 1.4
A25: Benin | B25: BEN | C25: 67.36027 | D25: 9.9 | E25: 42.913766 | F25: 0.42626804 | G25: 47.099998 | H25: 0.97 | I25: 1.3
A26: Bermuda | B26: BMU | C26: 99
A27: Bhutan | B27: BTN | C27: 99 | F27: 0.08899329 | G27: 72.099998 | H27: 0.96 | I27: 4.4
A28: Bolivia (Plurinational State of) | B28: BOL | C28: 94.11337 | D28: 19.4 | E28: 7.5000166 | F28: 0.081610249 | G28: 93.852562 | H28: 0.96 | I28: 0.9
A29: Bonaire, Sint Eustatius and Saba | B29: BES | C29: 99
A30: Bosnia and Herzegovina | B30: BIH | C30: 96.093474 | D30: 2.5 | E30: 0.04973027 | F30: 0.10700598 | G30: 98.300003 | H30: 0.98 | I30: 3.3
A31: Botswana | B31: BWA | C31: 92.567562 | D31: 22.9 | E31: 9.0563616 | F31: 0.43653807 | G31: 86.823181 | H31: 0.98 | I31: 1.6
A32: Brazil | B32: BRA | C32: 99 | D32: 4.7 | E32: 0.56737738 | F32: 0.12952284 | G32: 94.690002 | H32: 0.98 | I32: 2.5
A33: British Virgin Islands | B33: VGB | C33: 99
A34: Brunei Darussalam | B34: BRN | C34: 99 | G34: 97.589996 | H34: 0.97 | I34: 6.5
A35: Bulgaria | B35: BGR | C35: 99 | D35: 2.5 | G35: 98.419998 | H35: 0.98 | I35: 4.7
A36: Burkina Faso | B36: BFA | C36: 49.505874 | D36: 16.2 | F36: 0.59352314 | G36: 34.490002 | H36: 0.98 | I36: 3
A37: Burundi | B37: BDI | C37: 62.440975 | E37: 70.60278 | F37: 0.89029561 | G37: 75.540001 | H37: 0.98 | I37: 3.3
A38: Cabo Verde | B38: CPV | C38: 89.870725 | D38: 18.2 | F38: 0.18140341 | G38: 91 | H38: 0.97 | I38: 0.8
A39: Cambodia | B39: KHM | C39: 78.006504 | D39: 4.8 | E39: 4.5952475 | F39: 0.54177063 | G39: 83.779999 | H39: 0.98 | I39: 3.4
A40: Cameroon | B40: CMR | C40: 69.592553 | D40: 6.4 | E40: 36.977012 | F40: 0.42048961 | G40: 78.230003 | H40: 0.98 | I40: 2.6
...
